> Go语言中没有使用try...catch类似的异常处理机制，而是提供了panic和recover函数来处理所谓的运行时异常，也就是所谓的错误处理机制。配合defer语句和error接口开发者可以非常灵活地处理运行时的错误和异常。

## panic
```go
package main

import "fmt"

func printAllOperations(x int, y int) {
  sum, subtract, multiply, divide := x+y, x-y, x*y, x/y
  fmt.Printf("sum=%v, subtract=%v, multiply=%v, divide=%v \n", sum, subtract, multiply, divide)
}

func main() {
    x := 20
    y := 10
    printAllOperations(x, y)
    fmt.Println("Exiting main without any issues")
}
// On running this code, we will see the following output as expected.
// sum=30, subtract=10, multiply=200, divide=2 
// Exiting main without any issues


// But there is an issue here. Let us say we run method with y:=0

// panic: runtime error: integer divide by zero
// goroutine 1 [running]:
// main.printAllOperations(0x14, 0x0)
//  panic.go:22 +0x1b5
// main.main()
//  panic.go:8 +0x37
```

## defer
A defer statement pushes a function call onto a list. The list of saved calls is executed after 
the surrounding function returns.

defer语句把一个函数的调用压入到一个list,当包裹它的函数返回后才会执行defer的内容。

This means that when we defer a function, we are guaranteeing it’s execution at the end of its surrounding function.

这就意味着当我们defer一个func，就可以确保它在包裹它的func之后执行。

我们将利用这个特性来处理panic

## recover
recover是Go提供的一个函数，可以接管goroutine发生的panic.

recover只能用在deferred func的内部，如果你在正常的流程中调用recover(),他会返回nil.
然而，当goroutine is panicking,recover() 可以捕获到 panic value.

给上面的例子加入panic捕获：
```go
package main

import "fmt"

func printAllOperations(x int, y int) {
    defer func() {
        if r := recover(); r != nil {
            fmt.Printf("Recovering from panic in printAllOperations error is: %v \n", r)
        }
    }
    sum, subtract, multiply, divide := x+y, x-y, x*y, x/y
    fmt.Printf("sum=%v, subtract=%v, multiply=%v, divide=%v \n", sum, subtract, multiply, divide)
}

func main() {
    x := 20
    y := 0
    printAllOperations(x, y)
    fmt.Println("Exiting main without any issues")
}
```
When the code panics, this deferred function will take control of the goroutine and finish the execution.

Now, let us run the main function with x:=20 and y:=0 . The output is :
```
Recovering from panic in printAllOperations error is: runtime error: integer divide by zero 
Exiting main without any issues
```

当想要打印出panic data并且提供一个graceful exit, debugging and fix issue,上面的方法非常有用。

当时我们也可以借助panic recovery提供一个发生panic后的逻辑。

如上面的例子，如果用户给了invalid input,我们就只进行addition, subtraction and, multiplication.
```go
package main

import "fmt"

func printAllOperations(x int, y int) {
    defer func() {
        if r := recover(); r != nil {
            fmt.Printf("Recovering from panic in printAllOperations error is: %v \n", r)
            fmt.Println("Proceeding to alternative flow skipping division.")
            printOperationsSkipDivide(x, y)
        }
    }
    sum, subtract, multiply, divide := x+y, x-y, x*y, x/y
    fmt.Printf("sum=%v, subtract=%v, multiply=%v, divide=%v \n", sum, subtract, multiply, divide)
}

func printOperationsSkipDivide(x int, y int) {
   sum, subtract, multiply := x+y, x-y, x*y
   fmt.Printf("sum=%v, subtract=%v, multiply=%v \n", sum, subtract, multiply)
}

func main() {
    x := 20
    y := 0
    printAllOperations(x, y)
    fmt.Println("Exiting main without any issues")
}
```

If we now execute the code with x:=20 and y:=0 , we will get the following output:
```
Recovering from panic in printAllOperations error is: runtime error: integer divide by zero 
Proceeding to alternative flow skipping division.
sum=20, subtract=20, multiply=0 
Exiting main without any issues
```

## defer 的执行顺序
### 多个defer的执行顺序
```go
package main

import "fmt"

func main() {
    defer fmt.Println("main defer1")
    test()
    defer fmt.Println("main defer2")
}

func test() {
    defer func() {
        fmt.Println("test defer1")
    }()
    defer func() {
        fmt.Println("test defer2")
    }()
}
// test defer2
// test defer1
// main defer2
// main defer1
```
我们发现defer就像一个LIFO的栈，后defer的会先执行，且在函数退出时才会执行。

### defer与return的执行顺序
```go
package main

import "fmt"

func test() (i int) {
    defer func() {
        i++
        fmt.Println("test defer, i =", i)
    }()
    return i
}

func main() {
    ret := test()
    fmt.Println("test return:", ret)
}
// test defer, i = 1
// test return: 1
```
这次test函数的返回值变成了1，defer里面的“i++"修改了返回值。所以defer的执行时机应该是return之后，且返回值返回给调用方之前。

## goroutine 的 defer 和 recover
一个用到 recover 的程序，停掉了服务器内部一个失败的协程而不影响其他协程的工作。
```go
func server(workChan <-chan *Work) {
    for work := range workChan {
        go safelyDo(work)   // start the goroutine for that work
    }
}

func safelyDo(work *Work) {
    defer func() {
        if err := recover(); err != nil {
            log.Printf("Work failed with %s in %v", err, work)
        }
    }()
    do(work)
}
```
上边的代码，如果 do(work) 发生 panic，错误会被记录且协程会退出并释放，而其他协程不受影响。